<sdf version='1.4'>
  <model name='lwa4d'>
    <link name='arm_base_link'>
      <pose>0 0 0 0 -0 0</pose>
      <inertial>
        <pose>0 0 0.09 0 -0 0</pose>
        <mass>3.6</mass>
        <inertia>
          <ixx>0.0105408</ixx>
          <ixy>0</ixy>
          <ixz>0</ixz>
          <iyy>0.0105408</iyy>
          <iyz>0</iyz>
          <izz>0.00648</izz>
        </inertia>
      </inertial>
      <collision name='arm_base_link_collision'>
        <pose>0 0 0.005 0 -0 0</pose>
        <geometry>
          <box>
            <size>0.01 0.01 0.01</size>
          </box>
        </geometry>
      </collision>
      <visual name='arm_base_link_visual'>
        <pose>0 0 0.004 0 -0 0</pose>
        <geometry>
          <cylinder>
            <length>0.08</length>
            <radius>0.045</radius>
          </cylinder>
        </geometry>
      </visual>
      <velocity_decay>
        <linear>0</linear>
        <angular>0</angular>
      </velocity_decay>
    </link>
    <joint name='arm_base_joint' type='revolute'>
      <child>arm_base_link</child>
      <parent>world</parent>
      <axis>
        <limit>
          <lower>0</lower>
          <upper>0</upper>
        </limit>
        <dynamics>
          <damping>0</damping>
        </dynamics>
        <xyz>0 0 1</xyz>
      </axis>
    </joint>
    <link name='arm_1_link'>
      <pose>0 0 0.15 -3.14159 2.06823e-13 -3.14159</pose>
      <inertial>
        <pose>0 0.02 -0.15 0 -0 0</pose>
        <mass>3.6</mass>
        <inertia>
          <ixx>0.0105408</ixx>
          <ixy>0</ixy>
          <ixz>0</ixz>
          <iyy>0.0105408</iyy>
          <iyz>0</iyz>
          <izz>0.00648</izz>
        </inertia>
      </inertial>
      <collision name='arm_1_link_collision'>
        <pose>0 0 -0.15 0 -0 -3.14159</pose>
        <geometry>
          <mesh>
            <scale>1 1 1</scale>
            <uri>model://schunk_description/meshes/lwa4d/arm_1_link.stl</uri>
          </mesh>
        </geometry>
      </collision>
      <visual name='arm_1_link_visual'>
        <pose>0 0 -0.15 0 -0 -3.14159</pose>
        <geometry>
          <mesh>
            <scale>1 1 1</scale>
            <uri>model://schunk_description/meshes/lwa4d/arm_1_link.stl</uri>
          </mesh>
        </geometry>
      </visual>
      <velocity_decay>
        <linear>0</linear>
        <angular>0</angular>
      </velocity_decay>
    </link>
    <joint name='arm_1_joint' type='revolute'>
      <child>arm_1_link</child>
      <parent>arm_base_link</parent>
      <axis>
        <xyz>2.06823e-13 0 -1</xyz>
        <limit>
          <lower>-3.14159</lower>
          <upper>3.14159</upper>
          <effort>216</effort>
          <velocity>0.43633</velocity>
        </limit>
        <dynamics/>
      </axis>
    </joint>
    <link name='arm_2_link'>
      <pose>-3.10235e-14 0 0.3 1.5708 2.06823e-13 -3.14159</pose>
      <inertial>
        <pose>0 0.15 0 0 -0 0</pose>
        <mass>2</mass>
        <inertia>
          <ixx>0.00456066</ixx>
          <ixy>0</ixy>
          <ixz>0</ixz>
          <iyy>0.00456066</iyy>
          <iyz>0</iyz>
          <izz>0.003136</izz>
        </inertia>
      </inertial>
      <collision name='arm_2_link_collision'>
        <pose>0 0 0 0 -0 -3.14159</pose>
        <geometry>
          <mesh>
            <scale>1 1 1</scale>
            <uri>model://schunk_description/meshes/lwa4d/arm_2_link.stl</uri>
          </mesh>
        </geometry>
      </collision>
      <visual name='arm_2_link_visual'>
        <pose>0 0 0 0 -0 -3.14159</pose>
        <geometry>
          <mesh>
            <scale>1 1 1</scale>
            <uri>model://schunk_description/meshes/lwa4d/arm_2_link.stl</uri>
          </mesh>
        </geometry>
      </visual>
      <velocity_decay>
        <linear>0</linear>
        <angular>0</angular>
      </velocity_decay>
    </link>
    <joint name='arm_2_joint' type='revolute'>
      <child>arm_2_link</child>
      <parent>arm_1_link</parent>
      <axis>
        <xyz>1.01273e-24 1 -4.89658e-12</xyz>
        <limit>
          <lower>-3.14159</lower>
          <upper>3.14159</upper>
          <effort>216</effort>
          <velocity>0.43633</velocity>
        </limit>
        <dynamics/>
      </axis>
    </joint>
    <link name='arm_3_link'>
      <pose>-3.10235e-14 0 0.3 -3.14159 2.06823e-13 -3.14159</pose>
      <inertial>
        <pose>0 0.03 -0.39 0 -0 0</pose>
        <mass>2</mass>
        <inertia>
          <ixx>0.00456066</ixx>
          <ixy>0</ixy>
          <ixz>0</ixz>
          <iyy>0.00456066</iyy>
          <iyz>0</iyz>
          <izz>0.003136</izz>
        </inertia>
      </inertial>
      <collision name='arm_3_link_collision'>
        <pose>0 0 -0.39 0 -0 -3.14159</pose>
        <geometry>
          <mesh>
            <scale>1 1 1</scale>
            <uri>model://schunk_description/meshes/lwa4d/arm_3_link.stl</uri>
          </mesh>
        </geometry>
      </collision>
      <visual name='arm_3_link_visual'>
        <pose>0 0 -0.39 0 -0 -3.14159</pose>
        <geometry>
          <mesh>
            <scale>1 1 1</scale>
            <uri>model://schunk_description/meshes/lwa4d/arm_3_link.stl</uri>
          </mesh>
        </geometry>
      </visual>
      <velocity_decay>
        <linear>0</linear>
        <angular>0</angular>
      </velocity_decay>
    </link>
    <joint name='arm_3_joint' type='revolute'>
      <child>arm_3_link</child>
      <parent>arm_2_link</parent>
      <axis>
        <xyz>2.06823e-13 1.30524e-42 -1</xyz>
        <limit>
          <lower>-3.14159</lower>
          <upper>3.14159</upper>
          <effort>81.5</effort>
          <velocity>0.4189</velocity>
        </limit>
        <dynamics/>
      </axis>
    </joint>
    <link name='arm_4_link'>
      <pose>-1.11684e-13 -5.09043e-43 0.69 1.5708 2.06823e-13 3.14159</pose>
      <inertial>
        <pose>0 0.15 0 0 -0 0</pose>
        <mass>1.2</mass>
        <inertia>
          <ixx>0.0018597</ixx>
          <ixy>0</ixy>
          <ixz>0</ixz>
          <iyy>0.0018597</iyy>
          <iyz>0</iyz>
          <izz>0.00118815</izz>
        </inertia>
      </inertial>
      <collision name='arm_4_link_collision'>
        <pose>0 0 0 0 -0 -3.14159</pose>
        <geometry>
          <mesh>
            <scale>1 1 1</scale>
            <uri>model://schunk_description/meshes/lwa4d/arm_4_link.stl</uri>
          </mesh>
        </geometry>
      </collision>
      <visual name='arm_4_link_visual'>
        <pose>0 0 0 0 -0 -3.14159</pose>
        <geometry>
          <mesh>
            <scale>1 1 1</scale>
            <uri>model://schunk_description/meshes/lwa4d/arm_4_link.stl</uri>
          </mesh>
        </geometry>
      </visual>
      <velocity_decay>
        <linear>0</linear>
        <angular>0</angular>
      </velocity_decay>
    </link>
    <joint name='arm_4_joint' type='revolute'>
      <child>arm_4_link</child>
      <parent>arm_3_link</parent>
      <axis>
        <xyz>1.01276e-24 1 -4.89658e-12</xyz>
        <limit>
          <lower>-3.14159</lower>
          <upper>3.14159</upper>
          <effort>81.5</effort>
          <velocity>0.4189</velocity>
        </limit>
        <dynamics/>
      </axis>
    </joint>
    <link name='arm_5_link'>
      <pose>-1.11684e-13 -5.09043e-43 0.69 3.14159 2.06823e-13 3.14159</pose>
      <inertial>
        <pose>0 0.05 -0.24 0 -0 0</pose>
        <mass>0.2</mass>
        <inertia>
          <ixx>0.000116079</ixx>
          <ixy>0</ixy>
          <ixz>0</ixz>
          <iyy>0.000116079</iyy>
          <iyz>0</iyz>
          <izz>0.000198025</izz>
        </inertia>
      </inertial>
      <collision name='arm_5_link_collision'>
        <pose>0 0 -0.323 0 -0 -3.14159</pose>
        <geometry>
          <mesh>
            <scale>1 1 1</scale>
            <uri>model://schunk_description/meshes/lwa4d/arm_5_link.stl</uri>
          </mesh>
        </geometry>
      </collision>
      <visual name='arm_5_link_visual'>
        <pose>0 0 -0.323 0 -0 -3.14159</pose>
        <geometry>
          <mesh>
            <scale>1 1 1</scale>
            <uri>model://schunk_description/meshes/lwa4d/arm_5_link.stl</uri>
          </mesh>
        </geometry>
      </visual>
      <velocity_decay>
        <linear>0</linear>
        <angular>0</angular>
      </velocity_decay>
    </link>
    <joint name='arm_5_joint' type='revolute'>
      <child>arm_5_link</child>
      <parent>arm_4_link</parent>
      <axis>
        <xyz>2.06823e-13 -1.30524e-42 -1</xyz>
        <limit>
          <lower>-3.14159</lower>
          <upper>3.14159</upper>
          <effort>20.7</effort>
          <velocity>0.43633</velocity>
        </limit>
        <dynamics/>
      </axis>
    </joint>
    <link name='arm_6_link'>
      <pose>-1.78488e-13 -8.74509e-44 1.013 1.5708 2.06823e-13 3.14159</pose>
      <inertial>
        <pose>0 0.012 0.017 0 -0 0</pose>
        <mass>1.9</mass>
        <inertia>
          <ixx>0.00275</ixx>
          <ixy>0</ixy>
          <ixz>0</ixz>
          <iyy>0.004002</iyy>
          <iyz>0</iyz>
          <izz>0.00283</izz>
        </inertia>
      </inertial>
      <collision name='arm_6_link_collision'>
        <pose>0 0 0 3.14159 -2.06823e-13 3.14159</pose>
        <geometry>
          <mesh>
            <scale>1 1 1</scale>
            <uri>model://schunk_description/meshes/lwa4d/arm_6_link.stl</uri>
          </mesh>
        </geometry>
      </collision>
      <visual name='arm_6_link_visual'>
        <pose>0 0 0 3.14159 -2.06823e-13 3.14159</pose>
        <geometry>
          <mesh>
            <scale>1 1 1</scale>
            <uri>model://schunk_description/meshes/lwa4d/arm_6_link.stl</uri>
          </mesh>
        </geometry>
      </visual>
      <velocity_decay>
        <linear>0</linear>
        <angular>0</angular>
      </velocity_decay>
    </link>
    <joint name='arm_6_joint' type='revolute'>
      <child>arm_6_link</child>
      <parent>arm_5_link</parent>
      <axis>
        <xyz>1.01276e-24 1 -4.89658e-12</xyz>
        <limit>
          <lower>-2.0944</lower>
          <upper>2.0944</upper>
          <effort>15</effort>
          <velocity>1.2566</velocity>
        </limit>
        <dynamics/>
      </axis>
    </joint>
    <link name='arm_7_link'>
      <pose>-1.78488e-13 -8.74509e-44 1.013 9.79317e-12 2.06823e-13 3.14159</pose>
      <inertial>
        <pose>0 0 0.06 0 -0 0</pose>
        <mass>0.005</mass>
        <inertia>
          <ixx>1.63542e-06</ixx>
          <ixy>0</ixy>
          <ixz>0</ixz>
          <iyy>1.63542e-06</iyy>
          <iyz>0</iyz>
          <izz>2.25e-06</izz>
        </inertia>
      </inertial>
      <collision name='arm_7_link_collision'>
        <pose>0 0 0.06 0 -0 0</pose>
        <geometry>
          <cylinder>
            <length>0.035</length>
            <radius>0.03</radius>
          </cylinder>
        </geometry>
      </collision>
      <visual name='arm_7_link_visual'>
        <pose>0 0 0 0 -0 0</pose>
        <geometry>
          <mesh>
            <scale>1 1 1</scale>
            <uri>model://schunk_description/meshes/lwa4d/arm_7_link.stl</uri>
          </mesh>
        </geometry>
      </visual>
      <velocity_decay>
        <linear>0</linear>
        <angular>0</angular>
      </velocity_decay>
    </link>
    <joint name='arm_7_joint' type='revolute'>
      <child>arm_7_link</child>
      <parent>arm_6_link</parent>
      <axis>
        <xyz>-2.06823e-13 9.79317e-12 1</xyz>
        <limit>
          <lower>-2.0944</lower>
          <upper>2.0944</upper>
          <effort>15</effort>
          <velocity>1.2566</velocity>
        </limit>
        <dynamics/>
      </axis>
    </joint>
    <static>0</static>
    <plugin name='ros_control' filename='libgazebo_ros_control.so'/>
  </model>
</sdf>
