<?xml version="1.0" ?>
<!-- =================================================================================== -->
<!-- |    This document was autogenerated by xacro from robot_lwa4d.urdf.xacro         | -->
<!-- |    EDITING THIS FILE BY HAND IS NOT RECOMMENDED                                 | -->
<!-- =================================================================================== -->
<robot name="lwa4d" xmlns:xacro="http://www.ros.org/wiki/xacro">
  <!-- common stuff -->
  <material name="Schunk/LightGrey">
    <color rgba="0.7 0.7 0.7 1.0"/>
  </material>
  <material name="Schunk/DarkGrey">
    <color rgba="0.4 0.4 0.4 1.0"/>
  </material>
  <material name="Schunk/Black">
    <color rgba="0.0 0.0 0.0 1.0"/>
  </material>
  <material name="Schunk/DarkGolden">
    <color rgba="0.4 0.4 0.3 1.0"/>
  </material>
  <material name="Schunk/Blue">
    <color rgba="0.0 0.0 0.8 1.0"/>
  </material>
  <gazebo>
    <plugin filename="libgazebo_ros_control.so" name="ros_control">
      <!--robotNamespace>/</robotNamespace-->
      <!--robotSimType>gazebo_ros_control/DefaultRobotHWSim</robotSimType-->
    </plugin>
  </gazebo>
  <!-- calibration -->
  <!-- schunk lwa4d -->
  <!-- Used for fixing robot to Gazebo 'base_link' -->
  <link name="world"/>
  <!-- arm -->
  <joint name="arm_base_joint" type="fixed">
    <origin rpy="0 0 0" xyz="0 0 0"/>
    <parent link="world"/>
    <child link="arm_base_link"/>
  </joint>
  <link name="arm_base_link">
    <inertial>
      <mass value="3.6"/>
      <origin rpy="0 0 0" xyz="0 0 0.09"/>
      <inertia ixx="0.0105407957837" ixy="0.0" ixz="0.0" iyy="0.0105407957837" iyz="0.0" izz="0.00648"/>
    </inertial>
    <visual>
      <origin rpy="0 0 0" xyz="0 0 0.004"/>
      <geometry>
        <cylinder length="0.08" radius="0.045"/>
      </geometry>
      <material name="Schunk/Black"/>
    </visual>
    <collision>
      <origin rpy="0 0 0" xyz="0 0 0.005"/>
      <geometry>
        <box size="0.01 0.01 0.01"/>
      </geometry>
    </collision>
  </link>
  <joint name="arm_1_joint" type="revolute">
    <origin rpy="0 -3.14159265359 0" xyz="0 0 0.15"/>
    <parent link="arm_base_link"/>
    <child link="arm_1_link"/>
    <axis xyz="0 0 1"/>
    <calibration rising="0"/>
    <limit effort="216" lower="-3.14159265359" upper="3.14159265359" velocity="0.43633"/>
  </joint>
  <link name="arm_1_link">
    <inertial>
      <mass value="3.6"/>
      <origin rpy="0 0 0" xyz="0 0.02 -0.15"/>
      <inertia ixx="0.0105407957837" ixy="0.0" ixz="0.0" iyy="0.0105407957837" iyz="0.0" izz="0.00648"/>
    </inertial>
    <visual>
      <origin rpy="0 0 3.14159265359" xyz="0 0 -0.15"/>
      <geometry>
        <mesh filename="package://schunk_description/meshes/lwa4d/arm_1_link.stl"/>
      </geometry>
      <material name="Schunk/LightGrey"/>
    </visual>
    <collision>
      <origin rpy="0 0 3.14159265359" xyz="0 0 -0.15"/>
      <geometry>
        <mesh filename="package://schunk_description/meshes/lwa4d/arm_1_link.stl"/>
      </geometry>
    </collision>
  </link>
  <joint name="arm_2_joint" type="revolute">
    <origin rpy="-1.57079632679 0 0" xyz="0 0 -0.15"/>
    <parent link="arm_1_link"/>
    <child link="arm_2_link"/>
    <axis xyz="0 0 1"/>
    <calibration rising="0"/>
    <limit effort="216" lower="-3.14159265359" upper="3.14159265359" velocity="0.43633"/>
  </joint>
  <link name="arm_2_link">
    <inertial>
      <mass value="2.0"/>
      <origin rpy="0 0 0" xyz="0 0.15 0"/>
      <inertia ixx="0.0045606648424" ixy="0.0" ixz="0.0" iyy="0.0045606648424" iyz="0.0" izz="0.003136"/>
    </inertial>
    <visual>
      <origin rpy="0 0 3.14159265359" xyz="0 0 0"/>
      <geometry>
        <mesh filename="package://schunk_description/meshes/lwa4d/arm_2_link.stl"/>
      </geometry>
      <material name="Schunk/Black"/>
    </visual>
    <collision>
      <origin rpy="0 0 3.14159265359" xyz="0 0 0"/>
      <geometry>
        <mesh filename="package://schunk_description/meshes/lwa4d/arm_2_link.stl"/>
      </geometry>
    </collision>
  </link>
  <joint name="arm_3_joint" type="revolute">
    <origin rpy="1.57079632679 0 0" xyz="0 0 0"/>
    <parent link="arm_2_link"/>
    <child link="arm_3_link"/>
    <axis xyz="0 0 1"/>
    <calibration rising="0"/>
    <limit effort="81.5" lower="-3.14159265359" upper="3.14159265359" velocity="0.4189"/>
  </joint>
  <link name="arm_3_link">
    <inertial>
      <mass value="2.0"/>
      <origin rpy="0 0 0" xyz="0.0 0.03 -0.39"/>
      <inertia ixx="0.0045606648424" ixy="0.0" ixz="0.0" iyy="0.0045606648424" iyz="0.0" izz="0.003136"/>
    </inertial>
    <visual>
      <origin rpy="0 0 3.14159265359" xyz="0 0 -0.39"/>
      <geometry>
        <mesh filename="package://schunk_description/meshes/lwa4d/arm_3_link.stl"/>
      </geometry>
      <material name="Schunk/LightGrey"/>
    </visual>
    <collision>
      <origin rpy="0 0 3.14159265359" xyz="0 0 -0.39"/>
      <geometry>
        <mesh filename="package://schunk_description/meshes/lwa4d/arm_3_link.stl"/>
      </geometry>
    </collision>
  </link>
  <joint name="arm_4_joint" type="revolute">
    <origin rpy="-1.57079632679 0 0" xyz="0 0 -0.39"/>
    <parent link="arm_3_link"/>
    <child link="arm_4_link"/>
    <axis xyz="0 0 1"/>
    <limit effort="81.5" lower="-3.14159265359" upper="3.14159265359" velocity="0.4189"/>
  </joint>
  <link name="arm_4_link">
    <inertial>
      <mass value="1.2"/>
      <origin rpy="0 0 0" xyz="0 0.15 0.0"/>
      <inertia ixx="0.00185969925612" ixy="0.0" ixz="0.0" iyy="0.00185969925612" iyz="0.0" izz="0.00118815"/>
    </inertial>
    <visual>
      <origin rpy="0 0 3.14159265359" xyz="0 0 0"/>
      <geometry>
        <mesh filename="package://schunk_description/meshes/lwa4d/arm_4_link.stl"/>
      </geometry>
      <material name="Schunk/Black"/>
    </visual>
    <collision>
      <origin rpy="0 0 3.14159265359" xyz="0 0 0"/>
      <geometry>
        <mesh filename="package://schunk_description/meshes/lwa4d/arm_4_link.stl"/>
      </geometry>
    </collision>
  </link>
  <joint name="arm_5_joint" type="revolute">
    <origin rpy="1.57079632679 0 0" xyz="0 0 0"/>
    <parent link="arm_4_link"/>
    <child link="arm_5_link"/>
    <axis xyz="0 0 1"/>
    <calibration rising="0"/>
    <limit effort="20.7" lower="-3.14159265359" upper="3.14159265359" velocity="0.43633"/>
  </joint>
  <link name="arm_5_link">
    <inertial>
      <mass value="0.2"/>
      <origin rpy="0 0 0" xyz="0 0.05 -0.24"/>
      <inertia ixx="0.000116079120235" ixy="0.0" ixz="0.0" iyy="0.000116079120235" iyz="0.0" izz="0.000198025"/>
    </inertial>
    <visual>
      <origin rpy="0 0 3.14159265359" xyz="0 0 -0.323"/>
      <geometry>
        <mesh filename="package://schunk_description/meshes/lwa4d/arm_5_link.stl"/>
      </geometry>
      <material name="Schunk/LightGrey"/>
    </visual>
    <collision>
      <origin rpy="0 0 3.14159265359" xyz="0 0 -0.323"/>
      <geometry>
        <mesh filename="package://schunk_description/meshes/lwa4d/arm_5_link.stl"/>
      </geometry>
    </collision>
  </link>
  <joint name="arm_6_joint" type="revolute">
    <origin rpy="-1.57079632679 0 0" xyz="0 0 -0.323"/>
    <parent link="arm_5_link"/>
    <child link="arm_6_link"/>
    <axis xyz="0 0 1"/>
    <calibration rising="0"/>
    <limit effort="15" lower="-2.0943951" upper="2.0943951" velocity="1.2566"/>
  </joint>
  <link name="arm_6_link">
    <inertial>
      <origin rpy="0 0 0" xyz="0 0.012 0.017"/>
      <mass value="1.9"/>
      <inertia ixx="0.002750" ixy="0" ixz="0" iyy="0.004002" iyz="0" izz="0.002830"/>
    </inertial>
    <visual>
      <origin rpy="0 3.14159265359 0" xyz="0 0 0"/>
      <geometry>
        <mesh filename="package://schunk_description/meshes/lwa4d/arm_6_link.stl"/>
      </geometry>
      <material name="Schunk/Black"/>
    </visual>
    <collision>
      <origin rpy="0 3.14159265359 0" xyz="0 0 0"/>
      <geometry>
        <mesh filename="package://schunk_description/meshes/lwa4d/arm_6_link.stl"/>
      </geometry>
    </collision>
  </link>
  <joint name="arm_7_joint" type="revolute">
    <origin rpy="-1.57079632679 0 0" xyz="0 0 0"/>
    <parent link="arm_6_link"/>
    <child link="arm_7_link"/>
    <axis xyz="0 0 1"/>
    <calibration rising="0"/>
    <limit effort="15" lower="-2.0943951" upper="2.0943951" velocity="1.2566"/>
  </joint>
  <link name="arm_7_link">
    <inertial>
      <mass value="0.005"/>
      <origin rpy="0 0 0" xyz="0 0 0.06"/>
      <inertia ixx="1.6354160125e-06" ixy="0.0" ixz="0.0" iyy="1.6354160125e-06" iyz="0.0" izz="2.25e-06"/>
    </inertial>
    <visual>
      <origin rpy="0 0 0" xyz="0 0 0"/>
      <geometry>
        <mesh filename="package://schunk_description/meshes/lwa4d/arm_7_link.stl"/>
      </geometry>
      <material name="Schunk/LightGrey"/>
    </visual>
    <collision>
      <origin rpy="0 0 0" xyz="0 0 0.06"/>
      <geometry>
        <cylinder length="0.035" radius="0.03"/>
      </geometry>
    </collision>
  </link>
  <transmission name="arm_1_trans">
    <type>transmission_interface/SimpleTransmission</type>
    <joint name="arm_1_joint">
      <hardwareInterface>VelocityJointInterface</hardwareInterface>
    </joint>
    <actuator name="arm_1_motor">
      <mechanicalReduction>1</mechanicalReduction>
    </actuator>
  </transmission>
  <transmission name="arm_2_trans">
    <type>transmission_interface/SimpleTransmission</type>
    <joint name="arm_2_joint">
      <hardwareInterface>VelocityJointInterface</hardwareInterface>
    </joint>
    <actuator name="arm_2_motor">
      <mechanicalReduction>1</mechanicalReduction>
    </actuator>
  </transmission>
  <transmission name="arm_3_trans">
    <type>transmission_interface/SimpleTransmission</type>
    <joint name="arm_3_joint">
      <hardwareInterface>VelocityJointInterface</hardwareInterface>
    </joint>
    <actuator name="arm_3_motor">
      <mechanicalReduction>1</mechanicalReduction>
    </actuator>
  </transmission>
  <transmission name="arm_4_trans">
    <type>transmission_interface/SimpleTransmission</type>
    <joint name="arm_4_joint">
      <hardwareInterface>VelocityJointInterface</hardwareInterface>
    </joint>
    <actuator name="arm_4_motor">
      <mechanicalReduction>1</mechanicalReduction>
    </actuator>
  </transmission>
  <transmission name="arm_5_trans">
    <type>transmission_interface/SimpleTransmission</type>
    <joint name="arm_5_joint">
      <hardwareInterface>VelocityJointInterface</hardwareInterface>
    </joint>
    <actuator name="arm_5_motor">
      <mechanicalReduction>1</mechanicalReduction>
    </actuator>
  </transmission>
  <transmission name="arm_6_trans">
    <type>transmission_interface/SimpleTransmission</type>
    <joint name="arm_6_joint">
      <hardwareInterface>VelocityJointInterface</hardwareInterface>
    </joint>
    <actuator name="arm_6_motor">
      <mechanicalReduction>1</mechanicalReduction>
    </actuator>
  </transmission>
  <transmission name="arm_7_trans">
    <type>transmission_interface/SimpleTransmission</type>
    <joint name="arm_7_joint">
      <hardwareInterface>VelocityJointInterface</hardwareInterface>
    </joint>
    <actuator name="arm_7_motor">
      <mechanicalReduction>1</mechanicalReduction>
    </actuator>
  </transmission>
</robot>

