<?xml version="1.0" ?>
<!-- =================================================================================== -->
<!-- |    This document was autogenerated by xacro from robot_lwa4p_extended.urdf.xacro | -->
<!-- |    EDITING THIS FILE BY HAND IS NOT RECOMMENDED                                 | -->
<!-- =================================================================================== -->
<robot name="lwa4p_extended" xmlns:xacro="http://www.ros.org/wiki/xacro">
  <!-- common stuff -->
  <material name="Schunk/LightGrey">
    <color rgba="0.7 0.7 0.7 1.0"/>
  </material>
  <material name="Schunk/DarkGrey">
    <color rgba="0.4 0.4 0.4 1.0"/>
  </material>
  <material name="Schunk/Black">
    <color rgba="0.0 0.0 0.0 1.0"/>
  </material>
  <material name="Schunk/DarkGolden">
    <color rgba="0.4 0.4 0.3 1.0"/>
  </material>
  <material name="Schunk/Blue">
    <color rgba="0.0 0.0 0.8 1.0"/>
  </material>
  <gazebo>
    <plugin filename="libgazebo_ros_control.so" name="ros_control">
      <!--robotNamespace>/</robotNamespace-->
      <!--robotSimType>gazebo_ros_control/DefaultRobotHWSim</robotSimType-->
    </plugin>
  </gazebo>
  <!-- calibration -->
  <!-- schunk lwa4p_extended -->
  <!-- Used for fixing robot to Gazebo 'base_link' -->
  <link name="world"/>
  <!-- arm -->
  <joint name="arm_base_joint" type="fixed">
    <origin rpy="0 0 0" xyz="0 0 0"/>
    <parent link="world"/>
    <child link="arm_base_link"/>
  </joint>
  <link name="arm_base_link">
    <inertial>
      <mass value="2.0"/>
      <origin rpy="0 0 0" xyz="0 0 0.067"/>
      <inertia ixx="0.0045606648424" ixy="0.0" ixz="0.0" iyy="0.0045606648424" iyz="0.0" izz="0.003136"/>
    </inertial>
    <visual>
      <origin rpy="0 0 0" xyz="0 0 0"/>
      <geometry>
        <mesh filename="package://schunk_description/meshes/lwa4p_extended/arm_base_link.stl"/>
      </geometry>
    </visual>
    <collision>
      <origin rpy="0 0 0" xyz="0 0 0"/>
      <geometry>
        <mesh filename="package://schunk_description/meshes/lwa4p_extended/arm_base_link.stl"/>
      </geometry>
    </collision>
  </link>
  <joint name="arm_1_joint" type="revolute">
    <origin rpy="0 0 0" xyz="0 0 0.139"/>
    <parent link="arm_base_link"/>
    <child link="arm_1_link"/>
    <axis xyz="0 0 1"/>
    <calibration rising="0"/>
    <dynamics damping="0" friction="0"/>
    <!--limit effort="81.5" velocity="0.42" lower="-6.2831853" upper="6.2831853"/-->
    <limit effort="81.5" lower="-3.14159265359" upper="3.14159265359" velocity="0.42"/>
    <!--safety_controller k_position="20" k_velocity="50" soft_lower_limit="${-M_PI + 0.01}" soft_upper_limit="${M_PI - 0.01}" /-->
  </joint>
  <link name="arm_1_link">
    <inertial>
      <origin rpy="0 0 0" xyz="0.0 0.0662 0.0473"/>
      <mass value="0.8"/>
      <inertia ixx="0.002034" ixy="0.0" ixz="0.0" iyy="0.001437" iyz="0.000784" izz="0.00161"/>
    </inertial>
    <visual>
      <origin rpy="0 0 0" xyz="0 0 0"/>
      <geometry>
        <mesh filename="package://schunk_description/meshes/lwa4p_extended/arm_1_link.dae"/>
      </geometry>
    </visual>
    <collision>
      <origin rpy="0 0 0" xyz="0 0 0"/>
      <geometry>
        <mesh filename="package://schunk_description/meshes/lwa4p_extended/arm_1_collision.stl"/>
      </geometry>
    </collision>
  </link>
  <joint name="arm_2_joint" type="revolute">
    <origin rpy="1.5708 0 0" xyz="0 0 0.0915"/>
    <parent link="arm_1_link"/>
    <child link="arm_2_link"/>
    <axis xyz="0 0 1"/>
    <calibration rising="0"/>
    <dynamics damping="0" friction="0"/>
    <limit effort="48" lower="-2.0943951" upper="2.0943951" velocity="1.2566"/>
    <!--safety_controller k_position="20" k_velocity="50" soft_lower_limit="${-2.0943 + 0.01}" soft_upper_limit="${2.0943 - 0.01}" /-->
  </joint>
  <link name="arm_2_link">
    <inertial>
      <origin rpy="0 0 0" xyz="0 0.018 -0.018"/>
      <mass value="3.9"/>
      <inertia ixx="0.009780" ixy="0.0" ixz="0.0" iyy="0.013300" iyz="0.0" izz="0.009780"/>
    </inertial>
    <visual>
      <origin rpy="0 0 0" xyz="0 0 0"/>
      <geometry>
        <mesh filename="package://schunk_description/meshes/lwa4p_extended/arm_2_link.dae"/>
      </geometry>
    </visual>
    <collision>
      <origin rpy="0 0 0" xyz="0 0 0"/>
      <geometry>
        <mesh filename="package://schunk_description/meshes/lwa4p_extended/arm_2_link.dae"/>
      </geometry>
    </collision>
  </link>
  <joint name="arm_3_joint" type="revolute">
    <origin rpy="-1.5708 0 0" xyz="0 0 0"/>
    <parent link="arm_2_link"/>
    <child link="arm_3_link"/>
    <axis xyz="0 0 1"/>
    <calibration rising="0"/>
    <dynamics damping="0" friction="0"/>
    <!--limit effort="48" velocity="1.2566" lower="-6.2831853" upper="6.2831853"/-->
    <limit effort="48" lower="-3.14159265359" upper="3.14159265359" velocity="1.2566"/>
    <!--safety_controller k_position="20" k_velocity="25" soft_lower_limit="${-M_PI + 0.01}" soft_upper_limit="${M_PI - 0.01}" /-->
  </joint>
  <link name="arm_3_link">
    <inertial>
      <origin rpy="0 0 0" xyz="0.0 0.06247 0.23425"/>
      <mass value="1.94533"/>
      <inertia ixx="0.0344" ixy="0.0" ixz="0.0077" iyy="0.0362" iyz="0.0" izz="0.0052"/>
    </inertial>
    <visual>
      <origin rpy="0 0 0" xyz="0 0 0"/>
      <geometry>
        <mesh filename="package://schunk_description/meshes/lwa4p_extended/arm_3_link.dae"/>
      </geometry>
    </visual>
    <collision>
      <origin rpy="0 0 0" xyz="0 0 0"/>
      <geometry>
        <mesh filename="package://schunk_description/meshes/lwa4p_extended/arm_3_collision.stl"/>
      </geometry>
    </collision>
  </link>
  <joint name="arm_4_joint" type="revolute">
    <origin rpy="1.5708 0 0" xyz="0 0 0.45360"/>
    <parent link="arm_3_link"/>
    <child link="arm_4_link"/>
    <axis xyz="0 0 1"/>
    <calibration rising="0"/>
    <dynamics damping="0" friction="0"/>
    <limit effort="48" lower="-2.0943951" upper="2.0943951" velocity="1.2566"/>
    <!--safety_controller k_position="20" k_velocity="25" soft_lower_limit="${-2.0943951 + 0.01}" soft_upper_limit="${2.0943951 - 0.01}" /-->
  </joint>
  <link name="arm_4_link">
    <inertial>
      <origin rpy="0 0 0" xyz="0 0.018 -0.018"/>
      <mass value="3.9"/>
      <inertia ixx="0.009780" ixy="0.0" ixz="0.0" iyy="0.013300" iyz="0.0" izz="0.009780"/>
    </inertial>
    <visual>
      <origin rpy="0 0 0" xyz="0 0 0"/>
      <geometry>
        <mesh filename="package://schunk_description/meshes/lwa4p_extended/arm_4_link.dae"/>
      </geometry>
    </visual>
    <collision>
      <origin rpy="0 0 0" xyz="0 0 0"/>
      <geometry>
        <mesh filename="package://schunk_description/meshes/lwa4p_extended/arm_4_link.dae"/>
      </geometry>
    </collision>
  </link>
  <joint name="arm_5_joint" type="revolute">
    <origin rpy="-1.5708 0 0" xyz="0 0 0"/>
    <parent link="arm_4_link"/>
    <child link="arm_5_link"/>
    <axis xyz="0 0 1"/>
    <calibration rising="0"/>
    <dynamics damping="0" friction="0"/>
    <!--limit effort="48" velocity="1.2566" lower="-6.2831853" upper="6.2831853" /-->
    <limit effort="48" lower="-3.14159265359" upper="3.14159265359" velocity="1.2566"/>
    <!--safety_controller k_position="20" k_velocity="25" soft_lower_limit="${-M_PI + 0.01}" soft_upper_limit="${M_PI - 0.01}" /-->
  </joint>
  <link name="arm_5_link">
    <inertial>
      <origin rpy="0 0 0" xyz="0.0 0.04175 0.17026"/>
      <mass value="1.3297"/>
      <inertia ixx="0.01" ixy="0.0" ixz="-0.0031" iyy="0.0111" iyz="0.0" izz="0.0031"/>
    </inertial>
    <visual>
      <origin rpy="0 0 0" xyz="0 0 0"/>
      <geometry>
        <mesh filename="package://schunk_description/meshes/lwa4p_extended/arm_5_link.dae"/>
      </geometry>
    </visual>
    <collision>
      <origin rpy="0 0 0" xyz="0 0 0"/>
      <geometry>
        <mesh filename="package://schunk_description/meshes/lwa4p_extended/arm_5_collision.stl"/>
      </geometry>
    </collision>
  </link>
  <joint name="arm_6_joint" type="revolute">
    <origin rpy="1.5708 0 0" xyz="0 0 0.2986"/>
    <parent link="arm_5_link"/>
    <child link="arm_6_link"/>
    <axis xyz="0 0 1"/>
    <calibration rising="0"/>
    <dynamics damping="0" friction="0"/>
    <limit effort="15" lower="-2.0943951" upper="2.0943951" velocity="1.2566"/>
    <!--safety_controller k_position="20" k_velocity="25" soft_lower_limit="${-2.0943951 + 0.01}" soft_upper_limit="${2.0943951 - 0.01}" /-->
  </joint>
  <link name="arm_6_link">
    <inertial>
      <origin rpy="0 0 0" xyz="0 0.012 -0.012"/>
      <mass value="1.9"/>
      <inertia ixx="0.002750" ixy="0.0" ixz="0.0" iyy="0.004002" iyz="0.0" izz="0.002830"/>
    </inertial>
    <visual>
      <origin rpy="0 0 0" xyz="0 0 0"/>
      <geometry>
        <mesh filename="package://schunk_description/meshes/lwa4p_extended/arm_6_link.dae"/>
      </geometry>
    </visual>
    <collision>
      <origin rpy="0 0 0" xyz="0 0 0"/>
      <geometry>
        <mesh filename="package://schunk_description/meshes/lwa4p_extended/arm_6_link.dae"/>
      </geometry>
    </collision>
  </link>
  <joint name="arm_7_joint" type="revolute">
    <origin rpy="-1.5708 0 0" xyz="0 0 0"/>
    <parent link="arm_6_link"/>
    <child link="arm_7_link"/>
    <axis xyz="0 0 1"/>
    <calibration rising="0"/>
    <dynamics damping="0" friction="0"/>
    <limit effort="15" lower="-2.0943951" upper="2.0943951" velocity="1.2566"/>
    <!--safety_controller k_position="20" k_velocity="25" soft_lower_limit="${-2.0943951 + 0.01}" soft_upper_limit="${2.0943951 - 0.01}" /-->
  </joint>
  <link name="arm_7_link">
    <inertial>
      <mass value="0.01"/>
      <origin rpy="0 0 0" xyz="0 0 0.1"/>
      <inertia ixx="1.666666e-07" ixy="0.0" ixz="0.0" iyy="1.666666e-07" iyz="0.0" izz="1.666666e-07"/>
    </inertial>
  </link>
  <transmission name="arm_1_trans">
    <type>transmission_interface/SimpleTransmission</type>
    <joint name="arm_1_joint">
      <hardwareInterface>VelocityJointInterface</hardwareInterface>
    </joint>
    <actuator name="arm_1_motor">
      <mechanicalReduction>1</mechanicalReduction>
    </actuator>
  </transmission>
  <transmission name="arm_2_trans">
    <type>transmission_interface/SimpleTransmission</type>
    <joint name="arm_2_joint">
      <hardwareInterface>VelocityJointInterface</hardwareInterface>
    </joint>
    <actuator name="arm_2_motor">
      <mechanicalReduction>1</mechanicalReduction>
    </actuator>
  </transmission>
  <transmission name="arm_3_trans">
    <type>transmission_interface/SimpleTransmission</type>
    <joint name="arm_3_joint">
      <hardwareInterface>VelocityJointInterface</hardwareInterface>
    </joint>
    <actuator name="arm_3_motor">
      <mechanicalReduction>1</mechanicalReduction>
    </actuator>
  </transmission>
  <transmission name="arm_4_trans">
    <type>transmission_interface/SimpleTransmission</type>
    <joint name="arm_4_joint">
      <hardwareInterface>VelocityJointInterface</hardwareInterface>
    </joint>
    <actuator name="arm_4_motor">
      <mechanicalReduction>1</mechanicalReduction>
    </actuator>
  </transmission>
  <transmission name="arm_5_trans">
    <type>transmission_interface/SimpleTransmission</type>
    <joint name="arm_5_joint">
      <hardwareInterface>VelocityJointInterface</hardwareInterface>
    </joint>
    <actuator name="arm_5_motor">
      <mechanicalReduction>1</mechanicalReduction>
    </actuator>
  </transmission>
  <transmission name="arm_6_trans">
    <type>transmission_interface/SimpleTransmission</type>
    <joint name="arm_6_joint">
      <hardwareInterface>VelocityJointInterface</hardwareInterface>
    </joint>
    <actuator name="arm_6_motor">
      <mechanicalReduction>1</mechanicalReduction>
    </actuator>
  </transmission>
  <transmission name="arm_7_trans">
    <type>transmission_interface/SimpleTransmission</type>
    <joint name="arm_7_joint">
      <hardwareInterface>VelocityJointInterface</hardwareInterface>
    </joint>
    <actuator name="arm_7_motor">
      <mechanicalReduction>1</mechanicalReduction>
    </actuator>
  </transmission>
</robot>

